Workbook
Name sel_team: Assumptions!$B$3
Name media_rights_total: Assumptions!$B$6
Name media_rights_seasons: Assumptions!$B$7
Name share_media: Assumptions!$B$8
Name title_spons: Assumptions!$B$9
Name other_central_spons: Assumptions!$B$10
Name share_spons: Assumptions!$B$11
Name n_teams: Assumptions!$B$12
Name team_spons_base: Assumptions!$B$13
Name merch_base: Assumptions!$B$14
Name home_matches: Assumptions!$B$15
Name occupancy: Assumptions!$B$16
Name max_seats: Assumptions!$B$17
Name comp_share: Assumptions!$B$18
Name ticket_price: Assumptions!$B$19
Name match_day_cost: Assumptions!$B$20
Name match_fee_lakh: Assumptions!$B$21
Name match_fee_players: Assumptions!$B$22
Name league_matches: Assumptions!$B$23
Name support_staff: Assumptions!$B$24
Name ops_admin: Assumptions!$B$25
Name marketing: Assumptions!$B$26
Name travel: Assumptions!$B$27
Name bcci_fee_share: Assumptions!$B$28
Name prize_winner: Assumptions!$B$29
Name prize_runner: Assumptions!$B$30
Name prize_third: Assumptions!$B$31
Name prize_fourth: Assumptions!$B$32
Name spons_up_playoffs: Assumptions!$B$33
Name spons_up_title: Assumptions!$B$34
Name merch_up_playoffs: Assumptions!$B$35
Name merch_up_title: Assumptions!$B$36
Name po_games_playoffs: Assumptions!$B$37
Name po_games_title: Assumptions!$B$38
Name title_given_playoffs: Assumptions!$B$39
Name t_code: Teams!$A$2:$A$11
Name t_brand: Teams!$C$2:$C$11
Name t_capacity: Teams!$E$2:$E$11
Name t_fee: Teams!$F$2:$F$11
Name t_salary: Teams!$G$2:$G$11
Name t_playoff: Teams!$H$2:$H$11
Name brand_index: 'P&L'!$B$5
Name capacity: 'P&L'!$B$6
Name salary: 'P&L'!$B$7
Name fee: 'P&L'!$B$8

Sheet Assumptions
A1: IPL Franchise Model - Assumptions
A2: Yellow cells are inputs: change any of them and the P&L, Scenarios and Check sheets update.
A3: Selected team: | B3: CSK
A5: Input | B5: Value | C5: Unit | D5: Status | E5: Source / reason
A6: Central media rights, 2023-27 cycle | B6: 48390 | C6: INR cr | D6: verified | E6: https://scroll.in/field/1025995/ipl-media-rights-for-2023-27-sold-for-rs-48390-crore-star-india-win-tv-deal-viacom18-bag-digital
A7: Seasons in media-rights cycle | B7: 5 | C7: seasons | D7: verified | E7: Same deal: 2023-2027
A8: Franchise share of media rights | B8: 0.5 | C8: share | D8: assumption | E8: BCCI does not publish the split; secondary sources report 45-50% of central rights go to the 10 franchises (e.g. https://www.dezerv.in/newsletter/ipl-business-model-that-hit-sixer/). We use 50%.
A9: Title sponsorship per season | B9: 500 | C9: INR cr | D9: verified | E9: Tata, 2024-2028, Rs 2,500 crore total - Wikipedia IPL article citing Times of India (19 Jan 2024)
A10: Other central sponsorship per season | B10: 300 | C10: INR cr | D10: assumption | E10: Associate/official partner deals are not disclosed in total; order-of-magnitude estimate.
A11: Franchise share of central sponsorship | B11: 0.5 | C11: share | D11: assumption | E11: Same reported 45-50% split as media rights.
A12: Number of teams | B12: 10 | C12: teams | D12: verified | E12: IPL since 2022
A13: Team sponsorship, average brand | B13: 75 | C13: INR cr | D13: assumption | E13: Calibrated so a top franchise totals ~Rs 650-700 crore revenue, the range Houlihan Lokey's IPL Valuation Study 2025 gives for top franchises. Scaled per team by brand value / league-average brand value.
A14: Merchandise, average brand | B14: 10 | C14: INR cr | D14: assumption | E14: Merchandise is small in Indian sport; scaled by brand value like sponsorship.
A15: Home matches | B15: 7 | C15: matches | D15: verified | E15: 14 league games, half at home (Cricsheet 2022-2026 schedule)
A16: Stadium occupancy | B16: 0.9 | C16: share | D16: assumption | E16: IPL matches are routinely near sell-out; 90% leaves room for weaker fixtures.
A17: Max sellable seats | B17: 60000 | C17: seats | D17: assumption | E17: Caps very large grounds (Ahmedabad 132k) at a realistic paid-ticket level.
... A36: Merchandise uplift - won title | B36: 0.4 | C36: share | D36: assumption | E36: Fan demand spikes with a playoff run / title.
A37: Extra matches - made playoffs (non-winner) | B37: 2 | D37: assumption | E37: assumption: 1-3 playoff games
A38: Extra matches - won title | B38: 2.5 | D38: assumption | E38: assumption: 2-3 playoff games
A39: P(title | playoffs) | B39: 0.25 | D39: assumption | E39: Four teams reach the playoffs; we do not model playoff matchups.

Sheet Teams
A1: Team | B1: Franchise | C1: Brand value (USD m) | D1: Home ground | E1: Capacity | F1: Franchise fee (INR cr/yr) | G1: 2026 squad salary (INR cr) | H1: Model playoff chance
A2: CSK | B2: Chennai Super Kings | C2: 235 | D2: MA Chidambaram Stadium, Chennai | E2: 38200 | F2: 0 | G2: 120.6 | H2: 0.548
A3: DC | B3: Delhi Capitals | C3: 152 | D3: Arun Jaitley Stadium, Delhi | E3: 41000 | F3: 0 | G3: 121.2 | H3: 0.513
A4: GT | B4: Gujarat Titans | C4: 142 | D4: Narendra Modi Stadium, Ahmedabad | E4: 132000 | F4: 520 | G4: 123.05 | H4: 0.635
A5: KKR | B5: Kolkata Knight Riders | C5: 227 | D5: Eden Gardens, Kolkata | E5: 68000 | F5: 0 | G5: 118.55 | H5: 0.606
A6: LSG | B6: Lucknow Super Giants | C6: 122 | D6: Ekana Cricket Stadium, Lucknow | E6: 50100 | F6: 700 | G6: 120.45 | H6: 0.582
A7: MI | B7: Mumbai Indians | C7: 242 | D7: Wankhede Stadium, Mumbai | E7: 33100 | F7: 0 | G7: 124.45 | H7: 0.592
A8: PBKS | B8: Punjab Kings | C8: 141 | D8: Maharaja Yadavindra Singh Stadium, Mullanpur | E8: 38000 | F8: 0 | G8: 121.5 | H8: 0.567
A9: RR | B9: Rajasthan Royals | C9: 146 | D9: Sawai Mansingh Stadium, Jaipur | E9: 30000 | F9: 0 | G9: 118.35 | H9: 0.616
A10: RCB | B10: Royal Challengers Bengaluru | C10: 269 | D10: M Chinnaswamy Stadium, Bengaluru | E10: 40000 | F10: 0 | G10: 124.75 | H10: 0.704
A11: SRH | B11: Sunrisers Hyderabad | C11: 154 | D11: Rajiv Gandhi Intl Stadium, Hyderabad | E11: 39200 | F11: 0 | G11: 119.55 | H11: 0.598
A13: Sources: brand values - Houlihan Lokey IPL Valuation Study 2025; capacities - Wikipedia stadium pages; home ground derived from 2026 fixtures; salary from 2026 retention + auction records; playoff chance from src/impact_model.py.

Sheet P&L
A1: Franchise P&L - INR crore per season
A2: ="Team: "&sel_team
A4: Line | B4: Missed playoffs | C4: Made playoffs | D4: Won title | E4: How it is calculated
A5: Brand index (team / league avg) | B5: =INDEX(t_brand,MATCH(sel_team,t_code,0))/AVERAGE(t_brand)
A6: Stadium capacity | B6: =INDEX(t_capacity,MATCH(sel_team,t_code,0))
A7: Player salaries (INR cr) | B7: =INDEX(t_salary,MATCH(sel_team,t_code,0))
A8: Franchise fee (INR cr) | B8: =INDEX(t_fee,MATCH(sel_team,t_code,0))
A10: REVENUE
A11: Central media rights share | B11: =media_rights_total/media_rights_seasons*share_media/n_teams | C11: =media_rights_total/media_rights_seasons*share_media/n_teams | D11: =media_rights_total/media_rights_seasons*share_media/n_teams | E11: Cycle value / seasons x franchise share / 10 teams
A12: Central sponsorship share | B12: =(title_spons+other_central_spons)*share_spons/n_teams | C12: =(title_spons+other_central_spons)*share_spons/n_teams | D12: =(title_spons+other_central_spons)*share_spons/n_teams | E12: (Title + other central sponsors) x franchise share / 10
A13: Team sponsorships | B13: =team_spons_base*brand_index*(1+0) | C13: =team_spons_base*brand_index*(1+spons_up_playoffs) | D13: =team_spons_base*brand_index*(1+spons_up_title) | E13: Base x brand index x (1 + performance uplift)
A14: Ticketing (home matches) | B14: =home_matches*MIN(capacity,max_seats)*occupancy*(1-comp_share)*ticket_price/10^7 | C14: =home_matches*MIN(capacity,max_seats)*occupancy*(1-comp_share)*ticket_price/10^7 | D14: =home_matches*MIN(capacity,max_seats)*occupancy*(1-comp_share)*ticket_price/10^7 | E14: Home matches x sellable seats x occupancy x paid share x price
A15: Merchandise | B15: =merch_base*brand_index*(1+0) | C15: =merch_base*brand_index*(1+merch_up_playoffs) | D15: =merch_base*brand_index*(1+merch_up_title) | E15: Base x brand index x (1 + uplift)
A16: Prize money | B16: =0 | C16: =(prize_runner+prize_third+prize_fourth)/3 | D16: =prize_winner | E16: BCCI prize pot by finish
A17: Total revenue | B17: =SUM(B11:B16) | C17: =SUM(C11:C16) | D17: =SUM(D11:D16) | E17: Sum of revenue lines
A18: COSTS
A19: Player salaries | B19: =salary | C19: =salary | D19: =salary | E19: 2026 squad salary bill (Teams sheet)
A20: Match fees | B20: =match_fee_lakh*match_fee_players*(league_matches+0)/100 | C20: =match_fee_lakh*match_fee_players*(league_matches+po_games_playoffs)/100 | D20: =match_fee_lakh*match_fee_players*(league_matches+po_games_title)/100 | E20: Fee x 12 players x matches played
A21: Support staff | B21: =support_staff | C21: =support_staff | D21: =support_staff | E21: Input
A22: Operations & admin | B22: =ops_admin | C22: =ops_admin | D22: =ops_admin | E22: Input
A23: Marketing | B23: =marketing | C23: =marketing | D23: =marketing | E23: Input
A24: Travel | B24: =travel | C24: =travel | D24: =travel | E24: Input
A25: Match-day costs | B25: =match_day_cost*home_matches | C25: =match_day_cost*home_matches | D25: =match_day_cost*home_matches | E25: Cost per home match x home matches
A26: BCCI fee on team revenue | B26: =bcci_fee_share*(B13+B15) | C26: =bcci_fee_share*(C13+C15) | D26: =bcci_fee_share*(D13+D15) | E26: Share x (team sponsorships + merchandise)
A27: Total operating costs | B27: =SUM(B19:B26) | C27: =SUM(C19:C26) | D27: =SUM(D19:D26) | E27: Sum of cost lines
A28: PROFIT
A29: Operating profit | B29: =B17-B27 | C29: =C17-C27 | D29: =D17-D27 | E29: Total revenue - total operating costs
A30: Operating margin | B30: =B29/B17 | C30: =C29/C17 | D30: =D29/D17 | E30: Operating profit / revenue
A31: Franchise fee instalment (assumption) | B31: =fee | C31: =fee | D31: =fee | E31: LSG/GT 2021 bid / 10 years (assumption)
A32: Profit after franchise fee | B32: =B29-B31 | C32: =C29-C31 | D32: =D29-D31 | E32: Operating profit - franchise fee
A33: Central (fixed) share of revenue | B33: =(B11+B12)/B17 | C33: =(C11+C12)/C17 | D33: =(D11+D12)/D17 | E33: Central income / total revenue

Sheet Scenarios
A1: What is performance worth? Probability-weighted P&L
A3: P(make playoffs) | B3: =INDEX(t_playoff,MATCH(sel_team,t_code,0)) | C3: Defaults to the model's chance for the current squad; overwrite to test.
A4: P(title) | B4: =B3*title_given_playoffs
A6: Scenario | B6: Probability | C6: Revenue | D6: Operating profit
A7: Missed playoffs | B7: =1-B3 | C7: ='P&L'!B17 | D7: ='P&L'!B29
A8: Made playoffs (no title) | B8: =B3-B4 | C8: ='P&L'!C17 | D8: ='P&L'!C29
A9: Won title | B9: =B4 | C9: ='P&L'!D17 | D9: ='P&L'!D29
A10: Expected value | C10: =SUMPRODUCT(B7:B9,C7:C9) | D10: =SUMPRODUCT(B7:B9,D7:D9)
A12: Revenue at stake: title vs missed playoffs | C12: =C9-C7
A13: ...as % of missed-playoffs revenue | C13: =C12/C7

Sheet Check
A1: Python vs Excel (base case, default inputs)
A2: Python values come from src/economics.py with the same default inputs. If you change an input, Excel will differ from these stored values - that is expected.
A4: Team | B4: Line | C4: Scenario | D4: Python | E4: Excel (selected team) | F4: Difference
A5: CSK | B5: Total revenue | C5: missed_playoffs | D5: 687.2015 | E5: =IF(A5=sel_team,'P&L'!B17,"") | F5: =IF(E5="","",E5-D5)
A6: CSK | B6: Total operating costs | C6: missed_playoffs | D6: 285.5306 | E6: =IF(A6=sel_team,'P&L'!B27,"") | F6: =IF(E6="","",E6-D6)
A7: CSK | B7: Operating profit | C7: missed_playoffs | D7: 401.6709 | E7: =IF(A7=sel_team,'P&L'!B29,"") | F7: =IF(E7="","",E7-D7)
A8: CSK | B8: Total revenue | C8: made_playoffs | D8: 702.61 | E8: =IF(A8=sel_team,'P&L'!C17,"") | F8: =IF(E8="","",E8-D8)
A9: CSK | B9: Total operating costs | C9: made_playoffs | D9: 288.679 | E9: =IF(A9=sel_team,'P&L'!C27,"") | F9: =IF(E9="","",E9-D9)
A10: CSK | B10: Operating profit | C10: made_playoffs | D10: 413.931 | E10: =IF(A10=sel_team,'P&L'!C29,"") | F10: =IF(E10="","",E10-D10)
A11: CSK | B11: Total revenue | C11: won_title | D11: 726.7848 | E11: =IF(A11=sel_team,'P&L'!D17,"") | F11: =IF(E11="","",E11-D11)
A12: CSK | B12: Total operating costs | C12: won_title | D12: 291.6973 | E12: =IF(A12=sel_team,'P&L'!D27,"") | F12: =IF(E12="","",E12-D12)
A13: CSK | B13: Operating profit | C13: won_title | D13: 435.0876 | E13: =IF(A13=sel_team,'P&L'!D29,"") | F13: =IF(E13="","",E13-D13)
A14: DC | B14: Total revenue | C14: missed_playoffs | D14: 652.6186 | E14: =IF(A14=sel_team,'P&L'!B17,"") | F14: =IF(E14="","",E14-D14)
A15: DC | B15: Total operating costs | C15: missed_playoffs | D15: 278.4202 | E15: =IF(A15=sel_team,'P&L'!B27,"") | F15: =IF(E15="","",E15-D15)
A16: DC | B16: Operating profit | C16: missed_playoffs | D16: 374.1984 | E16: =IF(A16=sel_team,'P&L'!B29,"") | F16: =IF(E16="","",E16-D16)
A17: DC | B17: Total revenue | C17: made_playoffs | D17: 665.6459 | E17: =IF(A17=sel_team,'P&L'!C17,"") | F17: =IF(E17="","",E17-D17)
A18: DC | B18: Total operating costs | C18: made_playoffs | D18: 281.0923 | E18: =IF(A18=sel_team,'P&L'!C27,"") | F18: =IF(E18="","",E18-D18)
A19: DC | B19: Operating profit | C19: made_playoffs | D19: 384.5536 | E19: =IF(A19=sel_team,'P&L'!C29,"") | F19: =IF(E19="","",E19-D19)
A20: DC | B20: Total revenue | C20: won_title | D20: 685.2853 | E20: =IF(A20=sel_team,'P&L'!D17,"") | F20: =IF(E20="","",E20-D20)
A21: DC | B21: Total operating costs | C21: won_title | D21: 283.2036 | E21: =IF(A21=sel_team,'P&L'!D27,"") | F21: =IF(E21="","",E21-D21)
A22: DC | B22: Operating profit | C22: won_title | D22: 402.0817 | E22: =IF(A22=sel_team,'P&L'!D29,"") | F22: =IF(E22="","",E22-D22)
A23: GT | B23: Total revenue | C23: missed_playoffs | D23: 674.9063 | E23: =IF(A23=sel_team,'P&L'!B17,"") | F23: =IF(E23="","",E23-D23)
A24: GT | B24: Total operating costs | C24: missed_playoffs | D24: 279.3413 | E24: =IF(A24=sel_team,'P&L'!B27,"") | F24: =IF(E24="","",E24-D24)
A25: GT | B25: Operating profit | C25: missed_playoffs | D25: 395.565 | E25: =IF(A25=sel_team,'P&L'!B29,"") | F25: =IF(E25="","",E25-D25)
A26: GT | B26: Total revenue | C26: made_playoffs | D26: 687.6467 | E26: =IF(A26=sel_team,'P&L'!C17,"") | F26: =IF(E26="","",E26-D26)
A27: GT | B27: Total operating costs | C27: made_playoffs | D27: 281.956 | E27: =IF(A27=sel_team,'P&L'!C27,"") | F27: =IF(E27="","",E27-D27)
A28: GT | B28: Operating profit | C28: made_playoffs | D28: 405.6907 | E28: =IF(A28=sel_team,'P&L'!C29,"") | F28: =IF(E28="","",E28-D28)
A29: GT | B29: Total revenue | C29: won_title | D29: 706.7396 | E29: =IF(A29=sel_team,'P&L'!D17,"") | F29: =IF(E29="","",E29-D29)
A30: GT | B30: Total operating costs | C30: won_title | D30: 283.9579 | E30: =IF(A30=sel_team,'P&L'!D27,"") | F30: =IF(E30="","",E30-D30)
A31: GT | B31: Operating profit | C31: won_title | D31: 422.7817 | E31: =IF(A31=sel_team,'P&L'!D29,"") | F31: =IF(E31="","",E31-D31)
A32: KKR | B32: Total revenue | C32: missed_playoffs | D32: 714.3872 | E32: =IF(A32=sel_team,'P&L'!B17,"") | F32: =IF(E32="","",E32-D32)
A33: KKR | B33: Total operating costs | C33: missed_playoffs | D33: 282.7374 | E33: =IF(A33=sel_team,'P&L'!B27,"") | F33: =IF(E33="","",E33-D33)
A34: KKR | B34: Operating profit | C34: missed_playoffs | D34: 431.6497 | E34: =IF(A34=sel_team,'P&L'!B29,"") | F34: =IF(E34="","",E34-D34)
A35: KKR | B35: Total revenue | C35: made_playoffs | D35: 729.5661 | E35: =IF(A35=sel_team,'P&L'!C17,"") | F35: =IF(E35="","",E35-D35)
A36: KKR | B36: Total operating costs | C36: made_playoffs | D36: 285.8399 | E36: =IF(A36=sel_team,'P&L'!C27,"") | F36: =IF(E36="","",E36-D36)
A37: KKR | B37: Operating profit | C37: made_playoffs | D37: 443.7262 | E37: =IF(A37=sel_team,'P&L'!C29,"") | F37: =IF(E37="","",E37-D37)
A38: KKR | B38: Total revenue | C38: won_title | D38: 753.3038 | E38: =IF(A38=sel_team,'P&L'!D17,"") | F38: =IF(E38="","",E38-D38)
A39: KKR | B39: Total operating costs | C39: won_title | D39: 288.7708 | E39: =IF(A39=sel_team,'P&L'!D27,"") | F39: =IF(E39="","",E39-D39)
A40: KKR | B40: Operating profit | C40: won_title | D40: 464.5331 | E40: =IF(A40=sel_team,'P&L'!D29,"") | F40: =IF(E40="","",E40-D40)
A41: LSG | B41: Total revenue | C41: missed_playoffs | D41: 651.5834 | E41: =IF(A41=sel_team,'P&L'!B17,"") | F41: =IF(E41="","",E41-D41)
...
